Workbook

Sheet Passo a Passo
A3: 1 | B3: Atualização da aba RESULTADO
A4: 1.1 | B4: Insira uma coluna após a última coluna com dados do mês anterior
A5: 1.2 | B5: Cole os dados disponibilizados na planilha do P&L da data-base atual
A6: 1.3 | B6: Verifique se os dados estão corretos conforme as linhas da tabela
A7: 1.4 | B7: Atualize a fórmula de variação na útlima coluna
A10: 2 | B10: Atualização da aba P&L Mensal - Anualizado
A11: 2.1 | B11: Pular uma coluna e inserir a data-base atualizada
A12: 2.2 | B12: Colar as colunas da aba P&L Mensal, na mesma formatação utilizada na planilha
A13: 2.3 | B13: Verificar se os valores correspondem com a linha presente
A16: 3 | B16: Atualização da aba P&L Acumulado
A17: 3.1 | B17: Colar os dados disponibilizados na planilha do P&L
A20: 4 | B20: Atualização da aba Comparativo 2026 x 2025
A21: 4.1 | B21: Colar os dados da aba P&L Acumulado
A22: 4.2 | B22: Colar os dados da aba P&L Acumulado referente ao mesmo período do ano passado
A25: 5 | B25: Atualização do Dashboard Streamlit
A26: 5.1 | B26: Anexe no Claude a planilha BASE_DASHBOARD_PL_2026 e o código atual do stream lit, salvo na pasta "G:\Drives compartilhados\Area - FPA\FPA\29. Checks Contabilidade\2026\Nova pasta\streamlit_app.py"
A27: 5.2 | B27: Encaminhe ao Claude o seguinte prompt
B28: Atualização mensal do dashboard de P&L (Banco Bari). Anexei dois arquivos: - BASE_DASHBOARD_PL_2026.xlsx → a planilha com a nova data base - streamlit_app.py → o código atual do dashboard Quero que você atualize o CÓDIGO para a nova data base. NÃO altere a planilha. Antes de editar, investigue a planilha e o dashboard atual e mantenha EXATAMENTE o mesmo formato/layout visual do dashboard (ordem das seções, cards, gráficos, cabeçalhos, cores, textos fixos) — não altere nada na estrutura ou no design. Atualize SOMENTE os valores e as comparações. No final, me devolva APENAS o streamlit_app.py completo e atualizado. Antes de editar, siga estas regras: 1) Descubra a data base e o nº de meses acumulados do ano lendo a planilha (na aba "Comparativo 2026 x 2025", linha 0: o campo "Até:" dá o último mês, e "Proporção anual" = 12 / nº de meses). Confirme também em "P&L Acumulado". 2) Rótulos do comparativo são VARIÁVEIS conforme o mês. Use o padrão "Acum. NM 26" / "Acum. NM 25", onde N = nº de meses acumulados (maio = 5M, junho = 6M, julho = 7M, e assim por diante). Troque em TODOS os lugares do comparativo (títulos de seção, cards, "vs ...", cabeçalhos de tabela e de gráfico). NÃO altere o dicionário mes_para_trimestre (é outro recurso). 3) Comparativo 2026 x 2025: monte o comparativo cruzando as abas "Comparativo 2026 x 2025" E "P&L Acumulado" (não use apenas uma das duas como fonte). Leia as colunas de cada produto (Consignado/Imobiliário/Total) de forma DINÂMICA em cada bloco. Os blocos de 2026 e de 2025 podem ter número de colunas diferente (ex.: o de 2025 às vezes tem uma coluna extra "BANCO DIGITAL"). Não use offsets fixos de coluna. 4) NÃO deixe nenhum valor numérico chumbado no código. Os valores de carteira, comissão e amortização devem vir da planilha: - Carteira (Total): casar por "contains carteira". - Comissão 2025 (Total): casamento EXATO com "comissao" (para NÃO pegar "Receita Comissão CRI", que também contém "comissão"). - Amortização (Total): "contains amortizacao". 5) Aba P&L Mensal: leia TODOS os meses. Detecte cada bloco mensal pela DATA do cabeçalho (que tem os produtos 2 linhas abaixo), e não pelo texto "DATA BASE -->" — só o bloco de janeiro tem esse texto; os demais trazem só a data. 6) As abas Resultados, P&L Mensal, P&L Acumulado e Comparativo 2026 x 2025 leem as datas dinamicamente. Confirme que todas já enxergam o novo mês. 7) Antes de me entregar: valide rodando os carregadores contra a planilha, conferindo que os valores batem (Receitas, Resultado Contábil, Carteira, Comissão, Amortização, comparativo 2026 x 2025 etc.) e que o app executa SEM erros. Reforço: mantenha exatamente o mesmo layout/formato visual do dashboard — a única mudança permitida são os valores e as comparações. 8) Se a estrutura da planilha tiver mudado de um jeito que exija uma decisão minha (ex.: rótulo de um período que não se encaixa no padrão "NM", ou divergência entre as abas "Comparativo 2026 x 2025" e "P&L Acumulado"), me pergunte de forma objetiva antes de finalizar.
A45: 5.3 | B45: Copie o código enviado pelo Claude e acesse o editor do código no Github e cole o novo código
A47: 1º
A64: 2º
A81: 3º
A96: 5.4 | B96: Verifique se o dashboard foi atualizado e se TODOS os valores estão corretos
B97: https://pl-dashboard-bariv2-e8vph2fztfoysynznzbmes.streamlit.app/

Sheet Premissas
B2: Receita Externa Cebraco:
B3: Apresenta todas as receitas, exceto receita das ligadas: Banco e Hipo. Desconsidera Securitizadora, pois os valores são pagos em patrimônio separado, ou seja, a sec apenas faz a intermediação.
B4: Conta "7.1.7.99.00.000007", "RENDAS CALL CENTER (PESSOA FISICA)" do Balancete e do arquivo de Resultados da Contabilidade
B6: Receita de Serviços, Interchange e Comissão CRI
B7: Serviços >> Grupo 7.1.7 do cosif do Banco, da Hipotecária, da DI (conta cosif: 7.1.7.00.00), receita de despachante da Service (conta cosif: 7.1.7.80.00.000024) e receita Call Center da Poio (conta cosif: 7.1.7.80.00.000002) . No arquivo de "Receitas e Despesas Contabilidade", salvo no diretório "G:\Drives compartilhados\Area - FPA\FPA\29. Checks Contabilidade\2025" há toda a relação dos "de-paras" nas abas do BANCO e da HIPO.
B8: A conta cosif "7.1.7.99.00.00.000013 - COORDENADOR LÍDER", é alocada em Receita de CRI
B9: As contas cosif "7.1.7.99.00.00.000015 - RECEITA INTERCHANGE - FUNCAO CREDITO", "7.1.7.99.00.00.000016 - RECEITA INTERCHANGE - FUNCAO DEBITO" e "7.1.7.99.00.00.000017 - BOLETO DE DEPOSITO LIQUIDADO" são alocada em Receita de Interchange. A divisão entre Consignado e Imobiliário é feita da seguinte forma: 42,6% para Consignado e 57,4% para Imobiliário.
B11: Receita cobrança externa Cebraco
B12: Receitas de prestação de serviços das empresas terceiras.
B13: Valor extraído da planilha "TD_P&L (Total)" do check contábil, célula "D12"
B14: Esse valor deve coincidir com a soma das contas cosif (7.1.7.99.00.000005 e 7.1.7.99.00.000007) do balancete da Cebraco
B16: Resultado de Seguros
... B77: 2) As demais rúbricas contábeis do cartão são alocadas da seguinte forma: 1) 42,6% para o Consignado e 57,4% para o Imobiliário.
A79: Não estamos utilizando os critérios específicados dessa linha para baixo
B81: PART. CONTROLADAS (SEC)
B82: 1) O dados é o mesmo que está na planilha "RESULTADO" e correspondente ao lucro líquido da Sec
B84: Critério de Rateio Captação:
B85: Lógica até Abril/2023
B86: Cartão é o resultado da receita de float/despesa da carteira de crédito que gera juros (desconsidera Creliq).
B87: Imobiliário --> LCI + CDB/LC - IPCA e IGPM + Resultado de Swap.
B88: Consignado --> CDB/LC - Pré/DI
B89: Outros (Receita Financeira, FGC, DPGE, e LFS) --> rateado pela carteira de consignado e imobiliário.
B90: Lógica após Maio/2023
B91: Cartão é o resultado da receita de float/despesa da carteira de crédito.
B92: Consignado --> Consome a despesa até fechar a carteira de ativa e passiva, na seguinte ordem quanto faltar carteira: CDB/LC - Pré, CDB/LC - DI, LCI - Pré e LCI - DI e Resultado Swap (DI x Pré)
B93: Imobiliário --> LCI + CDB/LC - IPCA e IGPM + Resultado de Swap (DI x IPCA), e o restante LCI Pré e DI que não forem utilizadas para fechar a carteira do consignado.
... B108: A partir de julho/24: versão de Março/24 adequando os rateios para retirada do banco digital.

Sheet RESULTADO
B2: Mês | C2: =EOMONTH(D2,-1) -> 44926 | D2: 44957 | E2: 44985 | F2: 45016 | G2: 1º TRIM | I2: =EOMONTH(F2:F2,1) -> 45046 | J2: =EOMONTH(I2:I2,1) -> 45077 | K2: =EOMONTH(J2:J2,1) -> 45107 | M2: 2º TRIM | O2: 1º SEM | Q2: =EOMONTH(K2,1) -> 45138 | R2: =EOMONTH(Q2:Q2,1) -> 45169 | S2: =EOMONTH(R2:R2,1) -> 45199 | U2: 3º TRIM | W2: =EOMONTH(S2:S2,1) -> 45230 | X2: 45260 | Y2: =EOMONTH(X2:X2,1) -> 45291 | AA2: 4º TRIM | AC2: 2º SEM | AE2: 2023 | AG2: 45322 | AH2: =EOMONTH(AG2,1) -> 45351 | AI2: =EOMONTH(AH2,1) -> 45382 | AK2: 1º TRIM | AM2: =EOMONTH(AI2:AI2,1) -> 45412 | AN2: =EOMONTH(AM2:AM2,1) -> 45443 | AO2: =EOMONTH(AN2:AN2,1) -> 45473 | AQ2: 2º TRIM | AS2: 1º SEM | AU2: =EOMONTH(AO2,1) -> 45504 | AV2: =EOMONTH(AU2:AU2,1) -> 45535 | AW2: =EOMONTH(AV2:AV2,1) -> 45565 | AY2: 3º TRIM | BA2: =EOMONTH(AW2:AW2,1) -> 45596 | BB2: =EOMONTH(BA2:BA2,1) -> 45626 | BC2: =EOMONTH(BB2:BB2,1) -> 45657 | BE2: 4º TRIM | BG2: 2º SEM | BI2: 2024 | BJ2: =EOMONTH(BC2,1) -> 45688 | BK2: =EOMONTH(BJ2,1) -> 45716 | BL2: =EOMONTH(BK2,1) -> 45747 | BM2: =EOMONTH(BL2:BL2,1) -> 45777 | BN2: =EOMONTH(BM2:BM2,1) -> 45808 | BO2: =EOMONTH(BN2:BN2,1) -> 45838 | BP2: =EOMONTH(BO2,1) -> 45869 | BQ2: =EOMONTH(BP2:BP2,1) -> 45900 | BR2: 45930 | BS2: =EOMONTH(BR2:BR2,1) -> 45961 | BT2: =EOMONTH(BS2,1) -> 45991 | BU2: =EOMONTH(BT2,1) -> 46022 | BW2: 4º TRIM | BY2: 2º SEM | CA2: YTD | CC2: =EOMONTH(BU2,1) -> 46053 | CD2: =EOMONTH(CC2,1) -> 46081 | CE2: =EOMONTH(CD2,1) -> 46112 | CF2: =EOMONTH(CE2,1) -> 46142 | CG2: =EOMONTH(CF2,1) -> 46173 | CH2: =EOMONTH(CG2,1) -> 46203 | CI2: 46234 | CJ2: 46265
B3: Banco | C3: -1225882.7 | D3: -2256281.8 | E3: -551555.87 | F3: 6437130.8 | G3: =SUM(D3:F3) -> 3629293.1 | I3: -1840435.7 | J3: 471919.39 | K3: 2444762.5 | M3: =SUM(I3:K3) -> 1076246.2 | O3: =SUM(I3:K3,D3:F3) -> 4705539.4 | Q3: -13238.56 | R3: -260697.35 | S3: 5983559.6 | U3: =SUM(Q3:S3) -> 5709623.7 | W3: 2301934.6 | X3: 2390376.4 | Y3: 7139953.1 | AA3: =SUM(W3:Y3) -> 11832264 | AC3: =SUM(W3:Y3,Q3:S3) -> 17541888 | AE3: =O3+AC3 -> 22247427 | AG3: 135333.08 | AH3: 1351348.1 | AI3: 1607493.6 | AK3: =SUM(AG3:AI3) -> 3094174.8 | AM3: 1778241.2 | AN3: 668906.43 | AO3: 4951864.8 | AQ3: =SUM(AM3:AO3) -> 7399012.4 | AS3: =SUM(AM3:AO3,AG3:AI3) -> 10493187 | AU3: 1208517.6 | AV3: 1317888.3 | AW3: 3497673 | AY3: =SUM(AU3:AW3) -> 6024078.8 | BA3: 407091.3 | BB3: 2060889.3 | BC3: 9185197.5 | BE3: =SUM(BA3:BC3) -> 11653178 | BG3: =SUM(BA3:BC3,AU3:AW3) -> 17677257 | BI3: =AS3+BG3 -> 28170444 | BJ3: 1184338 | BK3: 476737.52 | BL3: 5719093.2 | BM3: 4177224.8 | BN3: 2356700.7 | BO3: 4784053.5 | BP3: 2422631.3 | BQ3: 2180653 | BR3: 3140838.3 | BS3: 462356.73 | BT3: 3972262 | BU3: 4603577 | BW3: =SUM(BS3:BU3) -> 9038195.8 | BY3: =SUM(BS3:BU3,BP3:BR3) -> 16782318 | CA3: =SUM(BJ3:BU3) -> 35480466 | CC3: 1868086.1 | CD3: 2667098.7 | CE3: 4416073.4 | CF3: 8042710.4 | CG3: =6557176.22 -> 6557176.2 | CH3: 5852018.8 | CI3: 5038945.8 | CJ3: 4569526.3
B4: Equiv.Patr. | C4: 453185.32 | D4: 771628.33 | E4: 1431454.9 | F4: 2102188.9 | G4: =SUM(D4:F4) -> 4305272.2 | I4: 436785.4 | J4: 417689.25 | K4: 2852793 | M4: =SUM(I4:K4) -> 3707267.6 | O4: =SUM(I4:K4,D4:F4) -> 8012539.8 | Q4: 554506.77 | R4: 852807.67 | S4: -43758.08 | U4: =SUM(Q4:S4) -> 1363556.4 | W4: 944140.65 | X4: 1170510.6 | Y4: -2091085.1 | AA4: =SUM(W4:Y4) -> 23566.16 | AC4: =SUM(W4:Y4,Q4:S4) -> 1387122.5 | AE4: =O4+AC4 -> 9399662.3 | AG4: 172056.15 | AH4: 533427.26 | AI4: 444797.31 | AK4: =SUM(AG4:AI4) -> 1150280.7 | AM4: 485176.53 | AN4: 762992.45 | AO4: 512552.2 | AQ4: =SUM(AM4:AO4) -> 1760721.2 | AS4: =SUM(AM4:AO4,AG4:AI4) -> 2911001.9 | AU4: 754648.1 | AV4: 477878.87 | AW4: -268578.25 | AY4: =SUM(AU4:AW4) -> 963948.72 | BA4: -655785.64 | BB4: 745429.73 | BC4: 1669542.1 | BE4: =SUM(BA4:BC4) -> 1759186.2 | BG4: =SUM(BA4:BC4,AU4:AW4) -> 2723134.9 | BI4: =AS4+BG4 -> 5634136.8 | BJ4: 541079.53 | BK4: 991900.92 | BL4: 1442485.3 | BM4: 1665618.3 | BN4: 1190816.5 | BO4: 1675707.9 | BP4: 1137988.6 | BQ4: 322307.46 | BR4: 869987.47 | BS4: 382306.92 | BT4: 1854232.9 | BU4: 1765324.5 | BW4: =SUM(BS4:BU4) -> 4001864.3 | BY4: =SUM(BS4:BU4,BP4:BR4) -> 6332147.9 | CA4: =SUM(BJ4:BU4) -> 13839756 | CC4: 1404277.8 | CD4: 1441916.6 | CE4: 1955492.4 | CF4: 3042605.6 | CG4: 1756796.8 | CH4: 3257355.9 | CI4: 2265684.8 | CJ4: 1860242.3
B5: JCP + Dividendos | C5: 191960.21 | D5: 0 | E5: 0 | F5: 0 | G5: =SUM(D5:F5) -> 0 | I5: 0 | J5: 0 | K5: 0 | M5: =SUM(I5:K5) -> 0 | O5: =SUM(I5:K5,D5:F5) -> 0 | Q5: 0 | R5: 0 | S5: 0 | U5: =SUM(Q5:S5) -> 0 | W5: 0 | X5: 0 | Y5: 4864009.9 | AA5: =SUM(W5:Y5) -> 4864009.9 | AC5: =SUM(W5:Y5,Q5:S5) -> 4864009.9 | AE5: =O5+AC5 -> 4864009.9 | AG5: 0 | AH5: 0 | AI5: 0 | AK5: =SUM(AG5:AI5) -> 0 | AM5: 0 | AN5: 0 | AO5: 1018230.3 | AQ5: =SUM(AM5:AO5) -> 1018230.3 | AS5: =SUM(AM5:AO5,AG5:AI5) -> 1018230.3 | AU5: 0 | AV5: 0 | AW5: 0 | AY5: =SUM(AU5:AW5) -> 0 | BA5: 0 | BB5: 0 | BC5: 683065.86 | BE5: =SUM(BA5:BC5) -> 683065.86 | BG5: =SUM(BA5:BC5,AU5:AW5) -> 683065.86 | BI5: =AS5+BG5 -> 1701296.2 | BJ5: 0 | BK5: 0 | BL5: 0 | BM5: 0 | BN5: 0 | BO5: 0 | BP5: 0 | BQ5: 0 | BR5: 0 | BS5: 0 | BT5: 0 | BU5: 0 | BW5: =SUM(BS5:BU5) -> 0 | BY5: =SUM(BS5:BU5,BP5:BR5) -> 0 | CA5: =SUM(BJ5:BU5) -> 0 | CC5: 0 | CD5: 0 | CE5: 0 | CF5: 0 | CG5: 0
B6: Resultado Banco | C6: -1871028.2 | D6: =D3-D4-D5 -> -3027910.1 | E6: =E3-E4-E5 -> -1983010.8 | F6: =F3-F4-F5 -> 4334941.8 | G6: =SUM(D6:F6) -> -675979.02 | I6: =I3-I4-I5 -> -2277221.1 | J6: =J3-J4-J5 -> 54230.14 | K6: =K3-K4-K5 -> -408030.44 | M6: =SUM(I6:K6) -> -2631021.4 | O6: =O3-O4-O5 -> -3307000.4 | Q6: =Q3-Q4-Q5 -> -567745.33 | R6: =R3-R4-R5 -> -1113505 | S6: =S3-S4-S5 -> 6027317.7 | U6: =SUM(Q6:S6) -> 4346067.3 | W6: 1357793.9 | X6: 1219865.8 | Y6: 4367028.2 | AA6: =SUM(W6:Y6) -> 6944688 | AC6: =AC3-AC4-AC5 -> 11290755 | AE6: =AE3-AE4-AE5 -> 7983754.9 | AG6: -36723.07 | AH6: 817920.86 | AI6: 1162696.3 | AK6: =SUM(AG6:AI6) -> 1943894.1 | AM6: 1293064.6 | AN6: -94086.02 | AO6: 3421082.3 | AQ6: =SUM(AM6:AO6) -> 4620060.9 | AS6: =AS3-AS4-AS5 -> 6563955 | AU6: 453869.49 | AV6: 840009.4 | AW6: 3766251.2 | AY6: =SUM(AU6:AW6) -> 5060130.1 | BA6: 1062876.9 | BB6: 1315459.6 | BC6: 6832589.5 | BE6: =SUM(BA6:BC6) -> 9210926.1 | BG6: =BG3-BG4-BG5 -> 14271056 | BI6: =BI3-BI4-BI5 -> 20835011 | BJ6: 643258.46 | BK6: -515163.4 | BL6: 4276607.9 | BM6: 2511606.5 | BN6: 1165884.2 | BO6: 3108345.6 | BP6: 1284642.7 | BQ6: 1858345.5 | BR6: 2270850.8 | BS6: 80049.81 | BT6: 2118029.2 | BU6: 2838252.5 | BW6: =SUM(BS6:BU6) -> 5036331.4 | BY6: =BY3-BY4-BY5 -> 10450170 | CA6: =SUM(BJ6:BU6) -> 21640710 | CC6: 463808.25 | CD6: 1225182.2 | CE6: =CE3-CE4 -> 2460581.1 | CF6: =CF3-CF4-CF5 -> 5000104.9 | CG6: =CG3-CG4-CG5 -> 4800379.4 | CH6: =CH3-CH4 -> 2594662.9 | CI6: 2773261 | CJ6: 2709283.9
B7: Hipotecária | C7: 569477.66 | D7: 184324.92 | E7: 1250477.1 | F7: 2071688.5 | G7: =SUM(D7:F7) -> 3506490.6 | I7: 411267.6 | J7: -80452.38 | K7: 2556900.1 | M7: =SUM(I7:K7) -> 2887715.3 | O7: =SUM(I7:K7,D7:F7) -> 6394205.9 | Q7: 370274.9 | R7: 507165.18 | S7: -90122.92 | U7: =SUM(Q7:S7) -> 787317.16 | W7: 886582.6 | X7: 857060.12 | Y7: 2345408.5 | AA7: =SUM(W7:Y7) -> 4089051.2 | AC7: =SUM(W7:Y7,Q7:S7) -> 4876368.4 | AE7: =O7+AC7 -> 11270574 | AG7: 110976.49 | AH7: 411297.69 | AI7: 236500.31 | AK7: =SUM(AG7:AI7) -> 758774.49 | AM7: 434611.59 | AN7: 404507.76 | AO7: 1338115.9 | AQ7: =SUM(AM7:AO7) -> 2177235.2 | AS7: =SUM(AM7:AO7,AG7:AI7) -> 2936009.7 | AU7: 617707.85 | AV7: 430066.94 | AW7: -305419.29 | AY7: =SUM(AU7:AW7) -> 742355.5 | BA7: -811427.31 | BB7: 850419.33 | BC7: 1712350.7 | BE7: =SUM(BA7:BC7) -> 1751342.7 | BG7: =SUM(BA7:BC7,AU7:AW7) -> 2493698.2 | BI7: =AS7+BG7 -> 5429707.9 | BJ7: 464703.12 | BK7: 871800.97 | BL7: 1249780.1 | BM7: 1592797.9 | BN7: 1100442.5 | BO7: 1636029.5 | BP7: 1078640.2 | BQ7: 108896.66 | BR7: 685150.93 | BS7: 198757.09 | BT7: 1665017.2 | BU7: 1403074.8 | BW7: =SUM(BS7:BU7) -> 3266849.1 | BY7: =SUM(BS7:BU7,BP7:BR7) -> 5139537 | CA7: =SUM(BJ7:BU7) -> 12055091 | CC7: 1359401.9 | CD7: 1158533.6 | CE7: 2104762.7 | CF7: 1998240.2 | CG7: =1774617.16 -> 1774617.2 | CH7: 2199968.1 | CI7: 1782672.4 | CJ7: 1028611.4
B8: Resultado Congl. Financeiro | C8: -1301550.5 | D8: -2843585.2 | E8: -732533.64 | F8: 6406630.4 | G8: =SUM(D8:F8) -> 2830511.5 | I8: -1865953.5 | J8: -26222.24 | K8: 2148869.7 | M8: =SUM(I8:K8) -> 256693.93 | O8: =SUM(I8:K8,D8:F8) -> 3087205.5 | Q8: -197470.43 | R8: -606339.84 | S8: 5937194.8 | U8: =SUM(Q8:S8) -> 5133384.5 | W8: 2244376.5 | X8: 2076926 | Y8: 6712436.7 | AA8: =SUM(W8:Y8) -> 11033739 | AC8: =SUM(W8:Y8,Q8:S8) -> 16167124 | AE8: =O8+AC8 -> 19254329 | AG8: 74253.42 | AH8: 1229218.5 | AI8: 1399196.6 | AK8: =SUM(AG8:AI8) -> 2702668.6 | AM8: 1727676.2 | AN8: 310421.74 | AO8: 4759198.2 | AQ8: =SUM(AM8:AO8) -> 6797296.1 | AS8: =SUM(AM8:AO8,AG8:AI8) -> 9499964.7 | AU8: 1071577.3 | AV8: 1270076.3 | AW8: 3460831.9 | AY8: =SUM(AU8:AW8) -> 5802485.6 | BA8: 251449.63 | BB8: 2165878.9 | BC8: 8544940.2 | BE8: =SUM(BA8:BC8) -> 10962269 | BG8: =SUM(BA8:BC8,AU8:AW8) -> 16764754 | BI8: =AS8+BG8 -> 26264719 | BJ8: =SUM(BJ6:BJ7) -> 1107961.6 | BK8: =SUM(BK6:BK7) -> 356637.57 | BL8: =SUM(BL6:BL7) -> 5526388 | BM8: =SUM(BM6:BM7) -> 4104404.4 | BN8: =SUM(BN6:BN7) -> 2266326.7 | BO8: =SUM(BO6:BO7) -> 4744375.1 | BP8: =SUM(BP6:BP7) -> 2363282.9 | BQ8: =SUM(BQ6:BQ7) -> 1967242.2 | ... BU8: =SUM(BU6:BU7) -> 4241327.3 | BW8: =SUM(BS8:BU8) -> 8303180.6 | BY8: =SUM(BS8:BU8,BP8:BR8) -> 15589707 | CA8: =SUM(CA6:CA7) -> 33695801 | CC8: =CC6+CC7 -> 1823210.1 | CD8: =CD6+CD7 -> 2383715.7 | CE8: =CE6+CE7 -> 4565343.7 | CF8: =CF6+CF7 -> 6998345 | CG8: =CG6+CG7 -> 6574996.5 | CH8: =CH6+CH7 -> 4794631.1 | CI8: 4555933.5 | CJ8: 3737895.3 | CK8: =(CJ8/CI8)-1 -> -0.17955445
B10: Apoio | C10: 3097.06 | D10: 45761.36 | E10: 41357.84 | F10: 179237.57 | G10: =SUM(D10:F10) -> 266356.77 | I10: -41623.05 | J10: 187462.07 | K10: -169417.16 | M10: =SUM(I10:K10) -> -23578.14 | O10: =SUM(I10:K10,D10:F10) -> 242778.63 | Q10: 63133.63 | R10: -208725.83 | S10: -304926.61 | U10: =SUM(Q10:S10) -> -450518.81 | W10: 64962.49 | X10: -408320.5 | Y10: -388305.66 | AA10: =SUM(W10:Y10) -> -731663.67 | AC10: =SUM(W10:Y10,Q10:S10) -> -1182182.5 | AE10: =O10+AC10 -> -939403.85 | AG10: 97102.96 | AH10: 301216.36 | AI10: -88491.62 | AK10: =SUM(AG10:AI10) -> 309827.7 | AM10: 113308.82 | AN10: 67062.17 | AO10: -111222.36 | AQ10: =SUM(AM10:AO10) -> 69148.63 | AS10: =SUM(AM10:AO10,AG10:AI10) -> 378976.33 | AU10: 103829.47 | AV10: -140484.96 | AW10: 170123.99 | AY10: =SUM(AU10:AW10) -> 133468.5 | BA10: -220088.02 | BB10: 900.53 | BC10: 94783.98 | BE10: =SUM(BA10:BC10) -> -124403.51 | BG10: =SUM(BA10:BC10,AU10:AW10) -> 9064.99 | BI10: =AS10+BG10 -> 388041.32 | BJ10: 8662.4 | BK10: -46398.02 | BL10: -198223.76 | BM10: 286595.95 | BN10: 250051.98 | BO10: 454587.93 | BP10: 531355.39 | BQ10: 457762.47 | BR10: 267242.22 | BS10: 668876.32 | BT10: 368998.71 | BU10: -137032.85 | BW10: =SUM(BS10:BU10) -> 900842.18 | BY10: =SUM(BS10:BU10,BP10:BR10) -> 2157202.3 | CA10: =SUM(BJ10:BL10)+SUM(BM10:BO10)+SUM(BP10:BR10)+SUM(BS10:BU10) -> 2912478.7 | CC10: -67205.14 | CD10: 307562.98 | CE10: 558365.81 | CF10: -249369.6 | CG10: =209420.16 -> 209420.16 | CH10: =438606.58 -> 438606.58 | CI10: 191269.86 | CJ10: 394267.68
B11: Service | C11: -682901.3 | D11: 992683.36 | E11: -497496.4 | F11: 560056.26 | G11: =SUM(D11:F11) -> 1055243.2 | I11: 50070 | J11: 52449.68 | K11: -58278.43 | M11: =SUM(I11:K11) -> 44241.25 | O11: =SUM(I11:K11,D11:F11) -> 1099484.5 | Q11: -107595.78 | R11: -143340.37 | S11: -49664.58 | U11: =SUM(Q11:S11) -> -300600.73 | W11: -83197.01 | X11: -191600.36 | Y11: -144210.21 | AA11: =SUM(W11:Y11) -> -419007.58 | AC11: =SUM(W11:Y11,Q11:S11) -> -719608.31 | AE11: =O11+AC11 -> 379876.16 | AG11: -132549.64 | AH11: -53812.19 | AI11: -164625.97 | AK11: =SUM(AG11:AI11) -> -350987.8 | AM11: -198315.59 | AN11: -50199.64 | AO11: 12376.66 | AQ11: =SUM(AM11:AO11) -> -236138.57 | AS11: =SUM(AM11:AO11,AG11:AI11) -> -587126.37 | AU11: -117486.72 | AV11: -47222 | AW11: 7254.56 | AY11: =SUM(AU11:AW11) -> -157454.16 | BA11: -74550.02 | BB11: -39497.45 | BC11: 46645.51 | BE11: =SUM(BA11:BC11) -> -67401.96 | BG11: =SUM(BA11:BC11,AU11:AW11) -> -224856.12 | BI11: =AS11+BG11 -> -811982.49 | BJ11: 21886.98 | BK11: -131785.62 | BL11: 92197.89 | BM11: 39268.28 | BN11: 324440.4 | BO11: 182046.23 | BP11: 167219.5 | BQ11: 129182.02 | BR11: 203916.29 | BS11: 245380.69 | BT11: 172928.84 | BU11: 212227.37 | BW11: =SUM(BS11:BU11) -> 630536.9 | BY11: =SUM(BS11:BU11,BP11:BR11) -> 1130854.7 | CA11: =SUM(BJ11:BL11)+SUM(BM11:BO11)+SUM(BP11:BR11)+SUM(BS11:BU11) -> 1658908.9 | CC11: 336620.5 | CD11: 238788.3 | CE11: 348085 | CF11: 319657.08 | CG11: =341150.66 -> 341150.66 | CH11: =377910.27 -> 377910.27 | CI11: 470112.91 | CJ11: 327634.99
B12: Sec | C12: -117389.37 | D12: 403864.17 | E12: 37532.65 | F12: 35087.87 | G12: =SUM(D12:F12) -> 476484.69 | I12: 20981.69 | J12: 302749.95 | K12: 24903.45 | M12: =SUM(I12:K12) -> 348635.09 | O12: =SUM(I12:K12,D12:F12) -> 825119.78 | Q12: 22459.15 | R12: 373949.41 | S12: 92606.79 | U12: =SUM(Q12:S12) -> 489015.35 | W12: 96234.81 | X12: 284203.71 | Y12: 192942.88 | AA12: =SUM(W12:Y12) -> 573381.4 | AC12: =SUM(W12:Y12,Q12:S12) -> 1062396.8 | AE12: =O12+AC12 -> 1887516.5 | AG12: 93813.74 | AH12: 135265.85 | AI12: 219542.37 | AK12: =SUM(AG12:AI12) -> 448621.96 | AM12: 114837.02 | AN12: 356560.25 | AO12: 208072.75 | AQ12: =SUM(AM12:AO12) -> 679470.02 | AS12: =SUM(AM12:AO12,AG12:AI12) -> 1128092 | AU12: 123558.82 | AV12: 40796.91 | AW12: 65236.66 | AY12: =SUM(AU12:AW12) -> 229592.39 | BA12: 171614.12 | BB12: -77824.7 | BC12: 584288.66 | BE12: =SUM(BA12:BC12) -> 678078.08 | BG12: =SUM(BA12:BC12,AU12:AW12) -> 907670.47 | BI12: =AS12+BG12 -> 2035762.5 | BJ12: 55268.02 | BK12: 91252.77 | BL12: 263356.18 | BM12: 62767.15 | BN12: 98598.14 | BO12: 54470.74 | BP12: 91139.91 | BQ12: 214580.78 | BR12: 198117.49 | BS12: 178204.25 | BT12: 188001.86 | BU12: 387325.03 | BW12: =SUM(BS12:BU12) -> 753531.14 | BY12: =SUM(BS12:BU12,BP12:BR12) -> 1257369.3 | CA12: =SUM(BJ12:BL12)+SUM(BM12:BO12)+SUM(BP12:BR12)+SUM(BS12:BU12) -> 1883082.3 | CC12: 56226.37 | CD12: 243037.75 | CE12: 521291.11 | CF12: 483457.04 | CG12: 491462.47 | CH12: 1118794.2 | CI12: 499564.42 | CJ12: 838499.34
B13: Cebraco | C13: 156241.1 | D13: 251871.21 | E13: 45403.03 | F13: 327936.67 | G13: =SUM(D13:F13) -> 625210.91 | I13: 138298.78 | J13: 144880.25 | K13: 186119.58 | M13: =SUM(I13:K13) -> 469298.61 | O13: =SUM(I13:K13,D13:F13) -> 1094509.5 | Q13: 141568.1 | R13: 89515.94 | S13: 134228.26 | U13: =SUM(Q13:S13) -> 365312.3 | W13: 216658.5 | X13: 190560.57 | Y13: 195389.68 | AA13: =SUM(W13:Y13) -> 602608.75 | AC13: =SUM(W13:Y13,Q13:S13) -> 967921.05 | AE13: =O13+AC13 -> 2062430.6 | AG13: 281362.26 | AH13: 228173.23 | AI13: 367935.48 | AK13: =SUM(AG13:AI13) -> 877470.97 | AM13: 416560.49 | AN13: 493559.89 | AO13: 254753.61 | AQ13: =SUM(AM13:AO13) -> 1164874 | AS13: =SUM(AM13:AO13,AG13:AI13) -> 2042345 | AU13: 414080.85 | AV13: 435825.79 | AW13: 431763.56 | AY13: =SUM(AU13:AW13) -> 1281670.2 | BA13: 305013.57 | BB13: 298153 | BC13: 244333.2 | BE13: =SUM(BA13:BC13) -> 847499.77 | BG13: =SUM(BA13:BC13,AU13:AW13) -> 2129170 | BI13: =AS13+BG13 -> 4171514.9 | BJ13: 383753.36 | BK13: 247766.94 | BL13: 197344.81 | BM13: 348062.45 | BN13: 323628.41 | BO13: 296101.84 | BP13: 214279.3 | BQ13: 295074.06 | BR13: 255574.77 | BS13: 270061.93 | BT13: 196618.29 | BU13: 334510.67 | BW13: =SUM(BS13:BU13) -> 801190.89 | BY13: =SUM(BS13:BU13,BP13:BR13) -> 1566119 | CA13: =SUM(BJ13:BL13)+SUM(BM13:BO13)+SUM(BP13:BR13)+SUM(BS13:BU13) -> 3362776.8 | CC13: 294487.17 | CD13: 193404.44 | CE13: 504122.76 | CF13: 345912.66 | CG13: =361593.45 -> 361593.45 | CH13: =441809.41 -> 441809.41 | CI13: 363630.38 | CJ13: 357928.67
B14: Marumbi | C14: -10022.49 | D14: 6101.14 | E14: 5599.87 | F14: 8798.99 | G14: =SUM(D14:F14) -> 20500 | I14: 7479.12 | J14: 9028.82 | K14: 91166.22 | M14: =SUM(I14:K14) -> 107674.16 | O14: =SUM(I14:K14,D14:F14) -> 128174.16 | Q14: -80984.46 | R14: 6475.46 | S14: -102983.23 | U14: =SUM(Q14:S14) -> -177492.23 | W14: 5833.58 | X14: 5190.32 | Y14: 4246.43 | AA14: =SUM(W14:Y14) -> 15270.33 | AC14: =SUM(W14:Y14,Q14:S14) -> -162221.9 | AE14: =O14+AC14 -> -34047.74 | AG14: 4972.24 | AH14: 4496.2 | AI14: -90847.58 | AK14: =SUM(AG14:AI14) -> -81379.14 | AM14: 4208.76 | AN14: 328.11 | AO14: 2786.93 | AQ14: =SUM(AM14:AO14) -> 7323.8 | AS14: =SUM(AM14:AO14,AG14:AI14) -> -74055.34 | AU14: -74768.8 | AV14: -131095.45 | AW14: 3837.14 | AY14: =SUM(AU14:AW14) -> -202027.11 | BA14: -100170.1 | BB14: -1819.17 | BC14: -2292.54 | BE14: =SUM(BA14:BC14) -> -104281.81 | BG14: =SUM(BA14:BC14,AU14:AW14) -> -306308.92 | BI14: =AS14+BG14 -> -380364.26 | BJ14: -2520.6 | BK14: -3154.34 | BL14: -2221.54 | BM14: -1911.07 | BN14: -1765.32 | BO14: -13358.99 | BP14: -12817.43 | BQ14: -13598.6 | BR14: -13542.27 | BS14: -13644.72 | BT14: -15611.28 | BU14: -14857.27 | BW14: =SUM(BS14:BU14) -> -44113.27 | BY14: =SUM(BS14:BU14,BP14:BR14) -> -84071.57 | CA14: =SUM(BJ14:BL14)+SUM(BM14:BO14)+SUM(BP14:BR14)+SUM(BS14:BU14) -> -109003.43 | CC14: -17113.78 | CD14: -14676.51 | CE14: -115574.2 | CF14: -20243.74 | CG14: -19919.31 | CH14: -28424.2 | CI14: -82721.05 | CJ14: -28038.71
B15: Tec | C15: -791480.18 | D15: 731451.37 | E15: -308631 | F15: 199923.47 | G15: =SUM(D15:F15) -> 622743.84 | I15: -21687.43 | J15: 10700.66 | K15: -2039.33 | M15: =SUM(I15:K15) -> -13026.1 | O15: =SUM(I15:K15,D15:F15) -> 609717.74 | Q15: -20611.62 | R15: 3981.71 | S15: 13111.09 | U15: =SUM(Q15:S15) -> -3518.82 | W15: -79586.88 | X15: -148771.42 | Y15: -71492.45 | AA15: =SUM(W15:Y15) -> -299850.75 | AC15: =SUM(W15:Y15,Q15:S15) -> -303369.57 | AE15: =O15+AC15 -> 306348.17 | AG15: -26043.14 | AH15: 8362.07 | AI15: 168585.77 | AK15: =SUM(AG15:AI15) -> 150904.7 | AM15: -24037.35 | AN15: -16277.97 | AO15: 1932.08 | AQ15: =SUM(AM15:AO15) -> -38383.24 | AS15: =SUM(AM15:AO15,AG15:AI15) -> 112521.46 | AU15: 45009.27 | AV15: -19884.46 | AW15: -1861.78 | AY15: =SUM(AU15:AW15) -> 23263.03 | BA15: -67172.13 | BB15: -2038.33 | BC15: -6070.28 | BE15: =SUM(BA15:BC15) -> -75280.74 | BG15: =SUM(BA15:BC15,AU15:AW15) -> -52017.71 | BI15: =AS15+BG15 -> 60503.75 | BJ15: -40549.83 | BK15: -34014.34 | BL15: 2298.89 | BM15: 253236.47 | BN15: -91675.21 | BO15: -113088.48 | BP15: -139859.02 | BQ15: -10120.06 | BR15: -59334.21 | BS15: 186513.9 | BT15: -75603.34 | BU15: 32313.39 | BW15: =SUM(BS15:BU15) -> 143223.95 | BY15: =SUM(BS15:BU15,BP15:BR15) -> -66089.34 | CA15: =SUM(BJ15:BU15) -> -89881.84 | CC15: 6528.27 | CD15: -37526.59 | CE15: 76283.56 | CF15: 249.65 | CG15: =31564.18 -> 31564.18 | CH15: =38995.65 -> 38995.65 | CI15: 52818.07 | CJ15: 31684.85
B16: Bariseg | C16: 384459.99 | D16: 392200.68 | E16: 398056.12 | F16: 375279.68 | G16: =SUM(D16:F16) -> 1165536.5 | I16: -14816.54 | J16: -10399 | K16: -2698.56 | M16: =SUM(I16:K16) -> -27914.1 | O16: =SUM(I16:K16,D16:F16) -> 1137622.4 | Q16: -1222.42 | R16: 13842.24 | S16: 56539.34 | U16: =SUM(Q16:S16) -> 69159.16 | W16: 31595.86 | X16: 25703.99 | Y16: -205781.68 | AA16: =SUM(W16:Y16) -> -148481.83 | AC16: =SUM(W16:Y16,Q16:S16) -> -79322.67 | AE16: =O16+AC16 -> 1058299.7 | AG16: 57666.95 | AH16: 27904.34 | AI16: 66053.48 | AK16: =SUM(AG16:AI16) -> 151624.77 | AM16: 89488.39 | AN16: 112473.42 | AO16: 112826.47 | AQ16: =SUM(AM16:AO16) -> 314788.28 | AS16: =SUM(AM16:AO16,AG16:AI16) -> 466413.05 | AU16: 105280.44 | AV16: 143270.29 | AW16: 159460.57 | AY16: =SUM(AU16:AW16) -> 408011.3 | BA16: 151077.13 | BB16: 187338.62 | BC16: 197245.09 | BE16: =SUM(BA16:BC16) -> 535660.84 | BG16: =SUM(BA16:BC16,AU16:AW16) -> 943672.14 | BI16: =AS16+BG16 -> 1410085.2 | BJ16: 207239.06 | BK16: 195013.08 | BL16: 144849.37 | BM16: 714727.3 | BN16: 777002.52 | BO16: 744540.08 | BP16: 672727.21 | BQ16: 726660.72 | BR16: 786885.56 | BS16: 1080237.8 | BT16: 791082.68 | BU16: 885803.25 | BW16: =SUM(BS16:BU16) -> 2757123.8 | BY16: =SUM(BS16:BU16,BP16:BR16) -> 4943397.3 | CA16: =SUM(BJ16:BU16) -> 7726768.7 | CC16: 828615.88 | CD16: 743112.13 | CE16: 853652.17 | CF16: 814124.26 | CG16: =855737.79 -> 855737.79 | CH16: =869844.14 -> 869844.14 | CI16: 855755.83 | CJ16: 922828.38
B17: DI | C17: 109356.42 | D17: 301296.69 | E17: 139257.8 | F17: 232489.41 | G17: =SUM(D17:F17) -> 673043.9 | I17: 263989.08 | J17: 49350.59 | K17: 39650.02 | M17: =SUM(I17:K17) -> 352989.69 | O17: =SUM(I17:K17,D17:F17) -> 1026033.6 | Q17: 112270.02 | R17: 124876.76 | S17: 45239.83 | U17: =SUM(Q17:S17) -> 282386.61 | W17: 134299.5 | X17: 83571.06 | Y17: 57294.26 | AA17: =SUM(W17:Y17) -> 275164.82 | AC17: =SUM(W17:Y17,Q17:S17) -> 557551.43 | AE17: =O17+AC17 -> 1583585 | AG17: 466252.26 | AH17: 248335.25 | AI17: 203476.8 | AK17: =SUM(AG17:AI17) -> 918064.31 | AM17: 282459.26 | AN17: 245432.29 | AO17: 206602.16 | AQ17: =SUM(AM17:AO17) -> 734493.71 | AS17: =SUM(AM17:AO17,AG17:AI17) -> 1652558 | AU17: 270758.64 | AV17: 266385.47 | AW17: 271784.93 | AY17: =SUM(AU17:AW17) -> 808929.04 | BA17: 249579.28 | BB17: 275812.11 | BC17: 211510.14 | BE17: =SUM(BA17:BC17) -> 736901.53 | BG17: =SUM(BA17:BC17,AU17:AW17) -> 1545830.6 | BI17: =AS17+BG17 -> 3198388.6 | BJ17: 240407.82 | BK17: 411839.17 | BL17: 279665.81 | BM17: 373531.63 | BN17: 295129.34 | BO17: 298405.16 | BP17: 423635.39 | BQ17: 406830.35 | BR17: 414584.86 | BS17: 503719.17 | BT17: 349160.14 | BU17: 326824.55 | BW17: =SUM(BS17:BU17) -> 1179703.9 | BY17: =SUM(BS17:BU17,BP17:BR17) -> 2424754.5 | CA17: =SUM(BJ17:BU17) -> 4323733.4 | CC17: 397092.06 | CD17: 252933.85 | CE17: 478274.25 | CF17: 370838.59 | CG17: =527546.49 -> 527546.49 | CH17: =546825.31 -> 546825.31 | CI17: 488496.52 | CJ17: 466122.93
B18: Bari Capital | BJ18: 25293.19 | BK18: 19767.84 | BL18: 20060.59 | BM18: 30800.68 | BN18: 15422.58 | BO18: 26663.53 | BP18: 51975.09 | BQ18: 44285.86 | BR18: 86107.31 | BS18: 79295.22 | BT18: 68143.26 | BU18: 77136.36 | BW18: =SUM(BS18:BU18) -> 224574.84 | BY18: =SUM(BS18:BU18,BP18:BR18) -> 406943.1 | CA18: =SUM(BJ18:BU18) -> 544951.51 | CC18: 113327.59 | CD18: -629.72 | CE18: -202789.07 | CF18: 23664.61 | CG18: -87553.01 | CH18: 15935.41 | CI18: 24659.56 | CJ18: 16626.2
B19: Resultado Coligadas | C19: -647967.51 | D19: 3413438.7 | E19: 76555.93 | F19: 1854471.9 | G19: =SUM(D19:F19) -> 5344466.5 | I19: 947786.42 | J19: 1044795.3 | K19: 383120.09 | M19: =SUM(I19:K19) -> 2375701.8 | O19: =SUM(I19:K19,D19:F19) -> 7720168.3 | Q19: 370689.56 | R19: 260575.32 | S19: -115849.11 | U19: =SUM(Q19:S19) -> 515415.77 | W19: 386800.85 | X19: -159462.63 | Y19: -359916.75 | AA19: =SUM(W19:Y19) -> -132578.53 | AC19: =SUM(W19:Y19,Q19:S19) -> 382837.24 | AE19: =O19+AC19 -> 8103005.5 | AG19: 842577.63 | AH19: 899941.11 | AI19: 681628.73 | AK19: =SUM(AG19:AI19) -> 2424147.5 | AM19: 798509.8 | AN19: 1208938.5 | AO19: 688128.3 | AQ19: =SUM(AM19:AO19) -> 2695576.6 | AS19: =SUM(AM19:AO19,AG19:AI19) -> 5119724.1 | AU19: 870261.97 | AV19: 547591.59 | AW19: 1107599.6 | AY19: =SUM(AU19:AW19) -> 2525453.2 | BA19: 415303.83 | BB19: 641024.61 | BC19: 1370443.8 | BE19: =SUM(BA19:BC19) -> 2426772.2 | BG19: =SUM(BA19:BC19,AU19:AW19) -> 4952225.4 | BI19: =AS19+BG19 -> 10071949 | BJ19: =SUM(BJ10:BJ18) -> 899440.4 | BK19: =SUM(BK10:BK18) -> 750287.48 | BL19: =SUM(BL10:BL18) -> 799328.24 | BM19: =SUM(BM10:BM18) -> 2107078.8 | BN19: =SUM(BN10:BN18) -> 1990832.8 | BO19: =SUM(BO10:BO18) -> 1930368 | BP19: =SUM(BP10:BP18) -> 1999655.3 | BQ19: =SUM(BQ10:BQ18) -> 2250657.6 | ... BU19: =SUM(BU10:BU18) -> 2104250.5 | BW19: =SUM(BS19:BU19) -> 7346614.3 | BY19: =SUM(BS19:BU19,BP19:BR19) -> 13736479 | CA19: =SUM(CA10:CA18) -> 22213815 | CC19: =SUM(CC10:CC18) -> 1948578.9 | CD19: =SUM(CD10:CD18) -> 1926006.6 | CE19: =SUM(CE10:CE18) -> 3021711.4 | CF19: =SUM(CF10:CF18) -> 2088290.6 | CG19: =SUM(CG10:CG18) -> 2711002.9 | CH19: =SUM(CH10:CH18) -> 3820296.8 | CI19: 2863586.5 | CJ19: 3327554.3 | CK19: =(CJ19/CI19)-1 -> 0.16202333
B21: Resultado Congl. + Coligadas | C21: -1949518 | D21: 569853.53 | E21: -655977.71 | F21: 8261102.2 | G21: =SUM(D21:F21) -> 8174978.1 | I21: -918167.08 | J21: 1018573 | K21: 2531989.8 | M21: =SUM(I21:K21) -> 2632395.7 | O21: =SUM(I21:K21,D21:F21) -> 10807374 | Q21: 173219.13 | R21: -345764.52 | S21: 5821345.6 | U21: =SUM(Q21:S21) -> 5648800.2 | W21: 2631177.4 | X21: 1917463.3 | Y21: 6352520 | AA21: =SUM(W21:Y21) -> 10901161 | AC21: =SUM(W21:Y21,Q21:S21) -> 16549961 | AE21: =O21+AC21 -> 27357335 | AG21: 916831.05 | AH21: 2129159.7 | AI21: 2080825.3 | AK21: =SUM(AG21:AI21) -> 5126816 | AM21: 2526186 | AN21: 1519360.3 | AO21: 5447326.5 | AQ21: =SUM(AM21:AO21) -> 9492872.7 | AS21: =SUM(AM21:AO21,AG21:AI21) -> 14619689 | AU21: 1941839.3 | AV21: 1817667.9 | AW21: 4568431.6 | AY21: =SUM(AU21:AW21) -> 8327938.8 | BA21: 666753.46 | BB21: 2806903.5 | BC21: 9915384 | BE21: =SUM(BA21:BC21) -> 13389041 | BG21: =SUM(BA21:BC21,AU21:AW21) -> 21716980 | BI21: =AS21+BG21 -> 36336669 | BJ21: =BJ8+BJ19 -> 2007402 | BK21: =BK8+BK19 -> 1106925.1 | BL21: =BL8+BL19 -> 6325716.2 | BM21: =BM8+BM19 -> 6211483.2 | BN21: =BN8+BN19 -> 4257159.5 | BO21: =BO8+BO19 -> 6674743.2 | BP21: =BP8+BP19 -> 4362938.2 | BQ21: =BQ8+BQ19 -> 4217899.8 | ... BU21: =BU8+BU19 -> 6345577.8 | BW21: =SUM(BS21:BU21) -> 15649795 | BY21: =SUM(BS21:BU21,BP21:BR21) -> 29326187 | CA21: =CA19+CA8 -> 55909616 | CC21: =CC8+CC19 -> 3771789.1 | CD21: =CD8+CD19 -> 4309722.3 | CE21: =CE8+CE19 -> 7587055.1 | CF21: =CF8+CF19 -> 9086635.6 | CG21: =CG8+CG19 -> 9285999.4 | CH21: =CH8+CH19 -> 8614927.9 | CI21: 7419520 | CJ21: 7065449.6 | CK21: =(CJ21/CI21)-1 -> -0.047721458
B23: BR Cards | C23: -744679.01 | D23: 2842467.5 | E23: -84774.05 | F23: 1734470.1 | G23: =SUM(D23:F23) -> 4492163.5 | I23: 336223.28 | J23: 424533.92 | K23: 146560.61 | M23: =SUM(I23:K23) -> 907317.81 | O23: =SUM(I23:K23,D23:F23) -> 5399481.3 | Q23: 91429.05 | R23: -137973.28 | S23: -239435.31 | U23: =SUM(Q23:S23) -> -285979.54 | W23: 273119.44 | X23: -431524.45 | Y23: -600734.72 | AA23: =SUM(W23:Y23) -> -759139.73 | AC23: =SUM(W23:Y23,Q23:S23) -> -1045119.3 | AE23: =O23+AC23 -> 4354362 | AG23: 767440.02 | AH23: 750979.9 | AI23: 432757.06 | AK23: =SUM(AG23:AI23) -> 1951177 | AM23: 662524.89 | AN23: 842029.62 | AO23: 593382.21 | AQ23: =SUM(AM23:AO23) -> 2097936.7 | AS23: =SUM(AM23:AO23,AG23:AI23) -> 4049113.7 | AU23: 744180.93 | AV23: 486306.52 | AW23: 1014721.4 | AY23: =SUM(AU23:AW23) -> 2245208.9 | BA23: 214691.41 | BB23: 875982.28 | BC23: 798970.02 | BE23: =SUM(BA23:BC23) -> 1889643.7 | BG23: =SUM(BA23:BC23,AU23:AW23) -> 4134852.6 | BI23: =AS23+BG23 -> 8183966.3 | BJ23: 828965.29 | BK23: 642854.08 | BL23: 537859.73 | BM23: 2092438.7 | BN23: 1856223.5 | BO23: 1915228.4 | BP23: 1829491.1 | BQ23: 2018509.1 | BR23: 2651795.3 | BS23: 2635218.8 | BT23: 1724928.1 | BU23: 1816891.3 | BW23: =SUM(BS23:BU23) -> 6177038.2 | BY23: =SUM(BS23:BU23,BP23:BR23) -> 12676834 | CA23: 21120255 | CC23: 1918146.6 | CD23: 1655619 | CE23: 2648896.4 | CF23: 1615034.6 | CG23: =2312442.5 -> 2312442.5 | CH23: 2732955.2 | CI23: 2399904.2 | CJ23: 2485883
B24: Resultado MEP | CC24: 1872781.9 | CD24: 1605888.7 | CE24: 2563268.6 | CF24: 1553760.1 | CG24: 2289452.1 | CH24: 2650413.2 | CI24: 2316461.2 | CJ24: 2453169.1
B25: Resulta Br Cards | CA25: =CA23-#REF!-#REF! -> #REF! | CC25: 45364.75 | CD25: 49730.27 | CE25: =CE23-CE24 -> 85627.77 | CF25: =CF23-CF24 -> 61274.51 | CG25: =CG23-CG24 -> 22990.37 | CH25: =CH23-CH24 -> 82542.05 | CI25: 83442.94 | CJ25: 32713.88
B26: RES. TOTAL | C26: =C21+#REF! -> #REF! | D26: =D21+#REF! -> #REF! | E26: =E21+#REF! -> #REF! | F26: =F21+#REF! -> #REF! | G26: =G21+#REF! -> #REF! | I26: =I21+#REF! -> #REF! | J26: =J21+#REF! -> #REF! | K26: =K21+#REF! -> #REF! | M26: =SUM(I26:K26) -> #REF! | O26: =SUM(I26:K26,D26:F26) -> #REF! | Q26: =Q21+#REF! -> #REF! | R26: =R21+#REF! -> #REF! | S26: =S21+#REF! -> #REF! | U26: =SUM(Q26:S26) -> #REF! | W26: =W21+#REF! -> #REF! | X26: =X21+#REF! -> #REF! | Y26: =Y21+#REF! -> #REF! | AA26: =SUM(W26:Y26) -> #REF! | AC26: =SUM(W26:Y26,Q26:S26) -> #REF! | AE26: =AE21+#REF! -> #REF! | AG26: =AG21+#REF! -> #REF! | AH26: =AH21+#REF! -> #REF! | AI26: =AI21+#REF! -> #REF! | AK26: =AK21+#REF! -> #REF! | AM26: =AM21+#REF! -> #REF! | AN26: =AN21+#REF! -> #REF! | AO26: =AO21+#REF! -> #REF! | AQ26: =SUM(AM26:AO26) -> #REF! | AS26: =SUM(AM26:AO26,AG26:AI26) -> #REF! | AU26: =AU21+#REF! -> #REF! | AV26: =AV21+#REF! -> #REF! | AW26: =AW21+#REF! -> #REF! | AY26: =SUM(AU26:AW26) -> #REF! | BA26: =BA21+#REF! -> #REF! | BB26: =BB21+#REF! -> #REF! | BC26: =BC21+#REF! -> #REF! | BE26: =SUM(BA26:BC26) -> #REF! | BG26: =SUM(BA26:BC26,AU26:AW26) -> #REF! | BI26: =BI21+#REF! -> #REF! | BJ26: =BJ21+#REF! -> #REF! | BK26: =BK21+#REF! -> #REF! | BL26: =BL21+#REF! -> #REF! | BM26: =BM21+#REF! -> #REF! | BN26: =BN21+#REF! -> #REF! | BO26: =BO21+#REF! -> #REF! | BP26: =BP21+#REF! -> #REF! | ... BU26: =BU21+#REF! -> #REF! | BW26: =SUM(BS26:BU26) -> #REF! | BY26: =#REF!+BW26 -> #REF! | CA26: =CA21+CA25 -> #REF! | CC26: =CC21+CC25 -> 3817153.8 | CD26: =CD21+CD25 -> 4359452.6 | CE26: =CE21+CE25 -> 7672682.9 | CF26: =CF21+CF25 -> 9147910.1 | CG26: =CG21+CG25 -> 9308989.8 | CH26: =CH21+CH25 -> 8697469.9 | CI26: 7502962.9 | CJ26: 7098163.5 | CK26: =(CJ26/CI26)-1 -> -0.053951935

Sheet P&L Mensal - Anualizado
A1: DATA BASE --> | B1: 46053 | M1: 46081 | X1: 46112 | AI1: 46142 | AT1: 46173 | BE1: 46174 | BH1: 46203 | BP1: 46204 | BS1: 46203 | CA1: 46235 | CD1: 46203
B3: CONSIGNADO | E3: IMOBILIARIO | H3: TOTAL | M3: CONSIGNADO | P3: IMOBILIARIO | S3: TOTAL | X3: CONSIGNADO | AA3: IMOBILIARIO | AD3: TOTAL | AI3: CONSIGNADO | AL3: IMOBILIARIO | AO3: TOTAL | AT3: CONSIGNADO | AW3: IMOBILIARIO | AZ3: TOTAL | BE3: CONSIGNADO | BH3: IMOBILIARIO | BK3: TOTAL | BP3: CONSIGNADO | BS3: IMOBILIARIO | BV3: TOTAL | CA3: CONSIGNADO | CD3: IMOBILIARIO | CG3: TOTAL
B4: Realizado | C4: Orçado | D4: ∆ (%) | E4: Realizado | F4: Orçado | G4: ∆ (%) | H4: Realizado | I4: Orçado | J4: ∆ (%) | K4: ∆ (R$) | M4: Realizado | N4: Orçado | O4: ∆ (%) | P4: Realizado | Q4: Orçado | R4: ∆ (%) | S4: Realizado | T4: Orçado | U4: ∆ (%) | V4: ∆ (R$) | X4: Realizado | Y4: Orçado | Z4: ∆ (%) | AA4: Realizado | AB4: Orçado | AC4: ∆ (%) | AD4: Realizado | AE4: Orçado | AF4: ∆ (%) | AG4: ∆ (R$) | AI4: Realizado | AJ4: Orçado | AK4: ∆ (%) | AL4: Realizado | AM4: Orçado | AN4: ∆ (%) | AO4: Realizado | AP4: Orçado | AQ4: ∆ (%) | AR4: ∆ (R$) | AT4: Realizado | AU4: Orçado | AV4: ∆ (%) | AW4: Realizado | AX4: Orçado | AY4: ∆ (%) | AZ4: Realizado | BA4: Orçado | BB4: ∆ (%) | BC4: ∆ (R$) | BE4: Realizado | BF4: Orçado | BG4: ∆ (%) | BH4: Realizado | BI4: Orçado | BJ4: ∆ (%) | BK4: Realizado | BL4: Orçado | BM4: ∆ (%) | BN4: ∆ (R$) | BP4: Realizado | BQ4: Orçado | BR4: ∆ (%) | BS4: Realizado | BT4: Orçado | BU4: ∆ (%) | BV4: Realizado | BW4: Orçado | BX4: ∆ (%) | BY4: ∆ (R$) | CA4: Realizado | CB4: Orçado | CC4: ∆ (%) | CD4: Realizado | CE4: Orçado | CF4: ∆ (%) | CG4: Realizado | CH4: Orçado | CI4: ∆ (%) | CJ4: ∆ (R$)
A5: RECEITAS | B5: 7802027.9 | C5: 7701714.3 | D5: 0.013024833 | E5: 23859887 | F5: 24532548 | G5: -0.027419124 | H5: 31661915 | I5: 32234263 | J5: -0.017755872 | K5: -572347.44 | M5: 7098724.1 | N5: 6991516.2 | O5: 0.015333991 | P5: 23773864 | Q5: 23417973 | R5: 0.015197351 | S5: 30872588 | T5: 30409489 | U5: 0.015228766 | V5: 463099 | X5: 7877352.9 | Y5: 7759392.7 | Z5: 0.015202255 | AA5: 33774613 | AB5: 29464374 | AC5: 0.14628643 | AD5: 41651965 | AE5: 37223767 | AF5: 0.11896159 | AG5: 4428198.4 | AI5: 7513769.7 | AJ5: 7551512 | AK5: -0.0049979825 | AL5: 34391853 | AM5: 27827307 | AN5: 0.23590304 | AO5: 41905623 | AP5: 35378819 | AQ5: 0.18448337 | AR5: 6526803.9 | AT5: 7585530.4 | AU5: 7837760.5 | AV5: -0.032181401 | AW5: 37483958 | AX5: 26639239 | AY5: 0.40709565 | AZ5: 45069488 | BA5: 34477000 | BB5: 0.30723347 | BC5: 10592488 | BE5: 7768119.1 | BF5: 7626952.8 | BG5: 0.018508878 | BH5: 34678251 | BI5: 29052906 | BJ5: 0.1936242 | BK5: 42446371 | BL5: 36679859 | BM5: 0.15721194 | BN5: 5766511.9 | BP5: 7825364.1 | BQ5: 7915101.7 | BR5: -0.011337516 | BS5: 32306467 | BT5: 29113454 | BU5: 0.10967483 | BV5: 40131831 | BW5: 37028556 | BX5: 0.083807632 | BY5: 3103275.6 | CA5: 7659976.8 | CB5: 7957281.7 | CC5: -0.037362619 | CD5: 28759886 | CE5: 29754492 | CF5: -0.0334271 | CG5: 36419863 | CH5: 37711774 | CI5: -0.034257505 | CJ5: -1291911.3
A6: Operações de Crédito | B6: 7793026.2 | C6: 7689247.8 | D6: 0.013496567 | E6: 21036305 | F6: 21210590 | G6: -0.0082168929 | H6: 28829331 | I6: 28899838 | J6: -0.0024396921 | K6: -70506.705 | M6: 7090560.7 | N6: 6979049.7 | O6: 0.015977969 | P6: 21137849 | Q6: 20364605 | R6: 0.037969994 | S6: 28228410 | T6: 27343655 | U6: 0.032356866 | V6: 884754.96 | X6: 7868473.4 | Y6: 7746926.1 | Z6: 0.015689749 | AA6: 29656161 | AB6: 26280606 | AC6: 0.12844279 | AD6: 37524634 | AE6: 34027532 | AF6: 0.10277271 | AG6: 3497101.8 | AI6: 7505271.2 | AJ6: 7539045.4 | AK6: -0.0044799064 | AL6: 30286317 | AM6: 24677939 | AN6: 0.22726283 | AO6: 37791589 | AP6: 32216985 | AQ6: 0.17303308 | AR6: 5574604 | AT6: 7577110.4 | AU6: 7825293.9 | AV6: -0.031715559 | AW6: 33233799 | AX6: 23584471 | AY6: 0.40913905 | AZ6: 40810910 | BA6: 31409765 | BB6: 0.29930642 | BC6: 9401144.5 | BE6: 7760330.2 | BF6: 7614486.2 | BG6: 0.019153487 | BH6: 29172318 | BI6: 25869138 | BJ6: 0.12768805 | BK6: 36932648 | BL6: 33483624 | BM6: 0.10300628 | BN6: 3449023.7 | BP6: 7817377.2 | BQ6: 7902635.1 | BR6: -0.010788542 | BS6: 27673852 | BT6: 25706086 | BU6: 0.076548649 | BV6: 35491229 | BW6: 33608721 | BX6: 0.056012493 | BY6: 1882508.3 | CA6: 7659976.8 | CB6: 7944815.2 | CC6: -0.035852102 | CD6: 24000775 | CE6: 26433124 | CF6: -0.092018977 | CG6: 31660752 | CH6: 34377940 | CI6: -0.079038692 | CJ6: -2717187.4
A7: Receita Juros | B7: 5986044.8 | C7: 5963467 | D7: 0.003786019 | E7: 17780387 | F7: 18019560 | G7: -0.01327294 | H7: 23766432 | I7: 23983027 | J7: -0.0090311673 | K7: -216594.73 | M7: 5423105.9 | N7: 5428491 | O7: -0.00099200565 | P7: 17032219 | Q7: 16315715 | R7: 0.043914918 | S7: 22455324 | T7: 21744206 | U7: 0.032703802 | V7: 711118.21 | X7: 6041460.8 | Y7: 6046154.6 | Z7: -0.00077634449 | AA7: 21983325 | AB7: 20556772 | AC7: 0.0693958 | AD7: 28024786 | AE7: 26602926 | AF7: 0.053447493 | AG7: 1421859.7 | AI7: 5722335.5 | AJ7: 5903016.4 | AK7: -0.030608248 | AL7: 18968832 | AM7: 19154707 | AN7: -0.009703897 | AO7: 24691167 | AP7: 25057724 | AQ7: -0.014628475 | AR7: -366556.29 | AT7: 5720927.6 | AU7: 6147095.5 | AV7: -0.069328331 | AW7: 20864074 | AX7: 18901932 | AY7: 0.10380643 | AZ7: 26585002 | BA7: 25049027 | BB7: 0.061318718 | BC7: 1535974.3 | BE7: 5951734.4 | BF7: 6000520.8 | BG7: -0.0081303582 | BH7: 18927414 | BI7: 20741537 | BJ7: -0.08746327 | BK7: 24879148 | BL7: 26742057 | BM7: -0.069662142 | BN7: -1862909 | BP7: 5950868.3 | BQ7: 6247547 | BR7: -0.047487227 | BS7: 21589769 | BT7: 20594778 | BU7: 0.048312772 | BV7: 27540637 | BW7: 26842325 | BX7: 0.026015337 | BY7: 698312.14 | CA7: 5808125.9 | CB7: 6300778.4 | CC7: -0.078189139 | CD7: 22603099 | CE7: 21164553 | CF7: 0.067969567 | CG7: 28411225 | CH7: 27465332 | CI7: 0.034439529 | CJ7: 945893.07
A10: Receita CM - Crédito Imobiliário | B10: 0 | C10: 0 | D10: - | E10: 2865754.8 | F10: 2790874.1 | G10: 0.026830562 | H10: 2865754.8 | I10: 2790874.1 | J10: 0.026830562 | K10: 74880.721 | M10: 0 | N10: 0 | O10: - | P10: 3752222.7 | Q10: 3641713.1 | R10: 0.030345476 | S10: 3752222.7 | T10: 3641713.1 | U10: 0.030345476 | V10: 110509.52 | X10: 0 | Y10: 0 | Z10: - | AA10: 7200722.4 | AB10: 5309468.9 | AC10: 0.35620388 | AD10: 7200722.4 | AE10: 5309468.9 | AF10: 0.35620388 | AG10: 1891253.4 | AI10: 0 | AJ10: 0 | AK10: - | AL10: 10881663 | AM10: 5098166.9 | AN10: 1.1344266 | AO10: 10881663 | AP10: 5098166.9 | AQ10: 1.1344266 | AR10: 5783496.4 | AT10: 0 | AU10: 0 | AV10: - | AW10: 11873778 | AX10: 4248792.5 | AY10: 1.7946242 | AZ10: 11873778 | BA10: 4248792.5 | BB10: 1.7946242 | BC10: 7624986 | BE10: 0 | BF10: 0 | BG10: - | BH10: 9615604.4 | BI10: 4701365 | BJ10: 1.0452793 | BK10: 9615604.4 | BL10: 4701365 | BM10: 1.0452793 | BN10: 4914239.4 | BP10: 0 | BQ10: 0 | BR10: - | BS10: 5589199.1 | BT10: 4675672.4 | BU10: 0.19537868 | BV10: 5589199.1 | BW10: 4675672.4 | BX10: 0.19537868 | BY10: 913526.71 | CA10: 0 | CB10: 0 | CC10: - | CD10: 729854.06 | CE10: 4821979.5 | CF10: -0.84864016 | CG10: 729854.06 | CH10: 4821979.5 | CI10: -0.84864016 | CJ10: -4092125.4
A11: Multa + Mora - Crédito Imobiliário | B11: 0 | C11: 0 | D11: - | E11: 348775.09 | F11: 358704.27 | G11: -0.027680676 | H11: 348775.09 | I11: 358704.27 | J11: -0.027680676 | K11: -9929.1765 | M11: 0 | N11: 0 | O11: - | P11: 312401.05 | Q11: 365724.09 | R11: -0.14580127 | S11: 312401.05 | T11: 365724.09 | U11: -0.14580127 | V11: -53323.037 | X11: 0 | Y11: 0 | Z11: - | AA11: 394865.93 | AB11: 372913.43 | AC11: 0.058867538 | AD11: 394865.93 | AE11: 372913.43 | AF11: 0.058867538 | AG11: 21952.496 | AI11: 0 | AJ11: 0 | AK11: - | AL11: 370357.59 | AM11: 383612.66 | AN11: -0.034553267 | AO11: 370357.59 | AP11: 383612.66 | AQ11: -0.034553267 | AR11: -13255.071 | AT11: 0 | AU11: 0 | AV11: - | AW11: 420468.1 | AX11: 392294.41 | AY11: 0.071817711 | AZ11: 420468.1 | BA11: 392294.41 | BB11: 0.071817711 | BC11: 28173.687 | BE11: 0 | BF11: 0 | BG11: - | BH11: 560900.65 | BI11: 384783.72 | BJ11: 0.4577037 | BK11: 560900.65 | BL11: 384783.72 | BM11: 0.4577037 | BN11: 176116.93 | BP11: 0 | BQ11: 0 | BR11: - | BS11: 425490.79 | BT11: 394182.82 | BU11: 0.079424986 | BV11: 425490.79 | BW11: 394182.82 | BX11: 0.079424986 | BY11: 31307.965 | CA11: 0 | CB11: 0 | CC11: - | CD11: 602666.7 | CE11: 405139.32 | CF11: 0.48755422 | CG11: 602666.7 | CH11: 405139.32 | CI11: 0.48755422 | CJ11: 197527.38
A12: Receita Juros - Cartão | B12: 1806981.4 | C12: 1725780.8 | D12: 0.047051542 | E12: 41388.299 | F12: 41452.468 | G12: -0.0015480233 | H12: 1848369.7 | I12: 1767233.2 | J12: 0.045911583 | K12: 81136.476 | M12: 1667454.8 | N12: 1550558.7 | O12: 0.075389688 | P12: 41006.606 | Q12: 41452.468 | R12: -0.010755986 | S12: 1708461.4 | T12: 1592011.1 | U12: 0.073146645 | V12: 116450.27 | X12: 1827012.7 | Y12: 1700771.4 | Z12: 0.074225863 | AA12: 77247.43 | AB12: 41452.468 | AC12: 0.86351823 | AD12: 1904260.1 | AE12: 1742223.9 | AF12: 0.093005376 | AG12: 162036.19 | AI12: 1782935.8 | AJ12: 1636029 | AK12: 0.089794723 | AL12: 65464.72 | AM12: 41452.468 | AN12: 0.57927195 | AO12: 1848400.5 | AP12: 1677481.5 | AQ12: 0.10189026 | AR12: 170919.02 | AT12: 1856182.8 | AU12: 1678198.5 | AV12: 0.10605676 | AW12: 75478.73 | AX12: 41452.468 | AY12: 0.82085008 | AZ12: 1931661.5 | BA12: 1719650.9 | BB12: 0.12328697 | BC12: 212010.56 | BE12: 1808595.8 | BF12: 1613965.5 | BG12: 0.12059139 | BH12: 68398.49 | BI12: 41452.468 | BJ12: 0.65004626 | BK12: 1876994.3 | BL12: 1655417.9 | BM12: 0.1338492 | BN12: 221576.37 | BP12: 1866508.9 | BQ12: 1655088.1 | BR12: 0.12773989 | BS12: 69393.13 | BT12: 41452.468 | BU12: 0.67404097 | BV12: 1935902 | BW12: 1696540.6 | BX12: 0.14108795 | BY12: 239361.43 | CA12: 1851850.9 | CB12: 1644036.8 | CC12: 0.12640478 | CD12: 65155.91 | CE12: 41452.468 | CF12: 0.57182221 | CG12: 1917006.8 | CH12: 1685489.2 | CI12: 0.13735926 | CJ12: 231517.56
A13: Receita Serviços | B13: 0 | C13: 0 | D13: - | E13: 1148925 | F13: 1642600 | G13: -0.30054484 | H13: 1148925 | I13: 1642600 | J13: -0.30054484 | K13: -493674.96 | M13: 0 | N13: 0 | O13: - | P13: 1421204 | Q13: 1591000 | R13: -0.10672279 | S13: 1421204 | T13: 1591000 | U13: -0.10672279 | V13: -169795.96 | X13: 0 | Y13: 0 | Z13: - | AA13: 2558364.6 | AB13: 1754400 | AC13: 0.45825613 | AD13: 2558364.6 | AE13: 1754400 | AF13: 0.45825613 | AG13: 803964.56 | AI13: 0 | AJ13: 0 | AK13: - | AL13: 1909358.2 | AM13: 1720000 | AN13: 0.11009201 | AO13: 1909358.2 | AP13: 1720000 | AQ13: 0.11009201 | AR13: 189358.25 | AT13: 0 | AU13: 0 | AV13: - | AW13: 2264503.4 | AX13: 1625400 | AY13: 0.39319759 | AZ13: 2264503.4 | BA13: 1625400 | BB13: 0.39319759 | BC13: 639103.37 | BE13: 0 | BF13: 0 | BG13: - | BH13: 2087666.2 | BI13: 1754400 | BJ13: 0.18996024 | BK13: 2087666.2 | BL13: 1754400 | BM13: 0.18996024 | BN13: 333266.25 | BP13: 0 | BQ13: 0 | BR13: - | BS13: 2315531.5 | BT13: 1978000 | BU13: 0.1706428 | BV13: 2315531.5 | BW13: 1978000 | BX13: 0.1706428 | BY13: 337531.46 | CA13: 0 | CB13: 0 | CC13: - | CD13: 1993030.1 | CE13: 1892000 | CF13: 0.053398589 | CG13: 1993030.1 | CH13: 1892000 | CI13: 0.053398589 | CJ13: 101030.13
A14: Receita Interchange | B14: 9001.6569 | C14: 12466.562 | D14: -0.27793588 | E14: 12128.993 | F14: 16829.858 | G14: -0.27931698 | H14: 21130.65 | I14: 29296.42 | J14: -0.27872928 | K14: -8165.77 | M14: 8163.3698 | N14: 12466.562 | O14: -0.34517872 | P14: 10999.47 | Q14: 16829.858 | R14: -0.34643121 | S14: 19162.84 | T14: 29296.42 | U14: -0.34589824 | V14: -10133.58 | X14: 8879.4971 | Y14: 12466.562 | Z14: -0.28773487 | AA14: 11964.393 | AB14: 16829.858 | AC14: -0.28909723 | AD14: 20843.89 | AE14: 29296.42 | AF14: -0.2885175 | AG14: -8452.53 | AI14: 8498.4553 | AJ14: 12466.562 | AK14: -0.31829998 | AL14: 11472.915 | AM14: 16829.858 | AN14: -0.31829998 | AO14: 19971.37 | AP14: 29296.42 | AQ14: -0.31829998 | AR14: -9325.05 | AT14: 8420.0255 | AU14: 12466.562 | AV14: -0.3245912 | AW14: 11367.034 | AX14: 16829.858 | AY14: -0.3245912 | AZ14: 19787.06 | BA14: 29296.42 | BB14: -0.3245912 | BC14: -9509.36 | BE14: 7788.9371 | BF14: 12466.562 | BG14: -0.37521369 | BH14: 10494.953 | BI14: 16829.858 | BJ14: -0.37640872 | BK14: 18283.89 | BL14: 29296.42 | BM14: -0.3759002 | BN14: -11012.53 | BP14: 7986.8823 | BQ14: 12466.562 | BR14: -0.3593356 | BS14: 10761.668 | BT14: 16829.858 | BU14: -0.360561 | BV14: 18748.55 | BW14: 29296.42 | BX14: -0.36003955 | BY14: -10547.87 | CA14: 0 | CB14: 12466.562 | CC14: -1 | CD14: 17196.73 | CE14: 16829.858 | CF14: 0.021798859 | CG14: 17196.73 | CH14: 29296.42 | CI14: -0.41300917 | CJ14: -12099.69
A15: Receita Comissão CRI | B15: 0 | C15: 0 | D15: - | E15: 0 | F15: 0 | G15: - | H15: 0 | I15: 0 | J15: - | K15: 0 | M15: 0 | N15: 0 | O15: - | P15: 0 | Q15: 0 | R15: - | S15: 0 | T15: 0 | U15: - | V15: 0 | X15: 0 | Y15: 0 | Z15: - | AA15: 0 | AB15: 0 | AC15: - | AD15: 0 | AE15: 0 | AF15: - | AG15: 0 | AI15: 0 | AJ15: 0 | AK15: - | AL15: 0 | AM15: 0 | AN15: - | AO15: 0 | AP15: 0 | AQ15: - | AR15: 0 | AT15: 0 | AU15: 0 | AV15: - | AW15: 0 | AX15: 0 | AY15: - | AZ15: 0 | BA15: 0 | BB15: - | BC15: 0 | BE15: 0 | BF15: 0 | BG15: - | BH15: 0 | BI15: 0 | BJ15: - | BK15: 0 | BL15: 0 | BM15: - | BN15: 0 | BP15: 0 | BQ15: 0 | BR15: - | BS15: 0 | BT15: 0 | BU15: - | BV15: 0 | BW15: 0 | BX15: - | BY15: 0 | CA15: 0 | CB15: 0 | CC15: - | CD15: 0 | CE15: 0 | CF15: - | CG15: 0 | CH15: 0 | CI15: - | CJ15: 0
A16: Receita Cobrança Ext. Cebraco | B16: 0 | C16: 0 | D16: - | E16: 364301.13 | F16: 364301.13 | G16: 0 | H16: 364301.13 | I16: 364301.13 | J16: 0 | K16: 0 | M16: 0 | N16: 0 | O16: - | P16: 168561.35 | Q16: 282753.77 | R16: -0.40385817 | S16: 168561.35 | T16: 282753.77 | U16: -0.40385817 | V16: -114192.42 | X16: 0 | Y16: 0 | Z16: - | AA16: 155899.01 | AB16: 282753.77 | AC16: -0.44864039 | AD16: 155899.01 | AE16: 282753.77 | AF16: -0.44864039 | AG16: -126854.76 | AI16: 0 | AJ16: 0 | AK16: - | AL16: 396916.38 | AM16: 282753.77 | AN16: 0.40375273 | AO16: 396916.38 | AP16: 282753.77 | AQ16: 0.40375273 | AR16: 114162.61 | AT16: 0 | AU16: 0 | AV16: - | AW16: 405034.85 | AX16: 282753.77 | AY16: 0.43246488 | AZ16: 405034.85 | BA16: 282753.77 | BB16: 0.43246488 | BC16: 122281.08 | BE16: 0 | BF16: 0 | BG16: - | BH16: 434422.58 | BI16: 282753.77 | BJ16: 0.53639888 | BK16: 434422.58 | BL16: 282753.77 | BM16: 0.53639888 | BN16: 151668.81 | BP16: 0 | BQ16: 0 | BR16: - | BS16: 379623.97 | BT16: 282753.77 | BU16: 0.3425956 | BV16: 379623.97 | BW16: 282753.77 | BX16: 0.3425956 | BY16: 96870.198 | CA16: 0 | CB16: 0 | CC16: - | CD16: 324764.68 | CE16: 282753.77 | CF16: 0.14857771 | CG16: 324764.68 | CH16: 282753.77 | CI16: 0.14857771 | CJ16: 42010.908
A17: Resultado de Seguros | B17: 0 | C17: 0 | D17: - | E17: 976784.38 | F17: 976784.38 | G17: 0 | H17: 976784.38 | I17: 976784.38 | J17: 0 | K17: 0 | M17: 0 | N17: 0 | O17: - | P17: 743112.13 | Q17: 900000 | R17: -0.17431986 | S17: 743112.13 | T17: 900000 | U17: -0.17431986 | V17: -156887.87 | X17: 0 | Y17: 0 | Z17: - | AA17: 1006702.7 | AB17: 900000 | AC17: 0.11855856 | AD17: 1006702.7 | AE17: 900000 | AF17: 0.11855856 | AG17: 106702.7 | AI17: 0 | AJ17: 0 | AK17: - | AL17: 948906.08 | AM17: 900000 | AN17: 0.054340089 | AO17: 948906.08 | AP17: 900000 | AQ17: 0.054340089 | AR17: 48906.08 | AT17: 0 | AU17: 0 | AV17: - | AW17: 1018281 | AX17: 900000 | AY17: 0.1314233 | AZ17: 1018281 | BA17: 900000 | BB17: 0.1314233 | BC17: 118280.97 | BE17: 0 | BF17: 0 | BG17: - | BH17: 1045395.2 | BI17: 900000 | BJ17: 0.16155027 | BK17: 1045395.2 | BL17: 900000 | BM17: 0.16155027 | BN17: 145395.24 | BP17: 0 | BQ17: 0 | BR17: - | BS17: 1027683.8 | BT17: 900000 | BU17: 0.14187087 | BV17: 1027683.8 | BW17: 900000 | BX17: 0.14187087 | BY17: 127683.78 | CA17: 0 | CB17: 0 | CC17: - | CD17: 1097822.6 | CE17: 900000 | CF17: 0.21980283 | CG17: 1097822.6 | CH17: 900000 | CI17: 0.21980283 | CJ17: 197822.55
A18: Resultado Brasil Cards | B18: 0 | C18: 0 | D18: - | E18: 65704.18 | F18: 65704.18 | G18: 0 | H18: 65704.18 | I18: 65704.18 | J18: 0 | K18: 0 | M18: 0 | N18: 0 | O18: - | P18: 49730.27 | Q18: -163.435 | R18: -305.28164 | S18: 49730.27 | T18: -163.435 | U18: -305.28164 | V18: 49893.705 | X18: 0 | Y18: 0 | Z18: - | AA18: 126708.72 | AB18: -163.435 | AC18: -776.2851 | AD18: 126708.72 | AE18: -163.435 | AF18: -776.2851 | AG18: 126872.15 | AI18: 0 | AJ18: 0 | AK18: - | AL18: 89809.88 | AM18: -163.435 | AN18: -550.51436 | AO18: 89809.88 | AP18: -163.435 | AQ18: 550.51436 | AR18: 89973.315 | AT18: 0 | AU18: 0 | AV18: - | AW18: 40616.85 | AX18: -163.435 | AY18: -249.5199 | AZ18: 40616.85 | BA18: -163.435 | BB18: 249.5199 | BC18: 40780.285 | BE18: 0 | BF18: 0 | BG18: - | BH18: 82542.05 | BI18: -163.435 | BJ18: -506.04512 | BK18: 82542.05 | BL18: -163.435 | BM18: 506.04512 | BN18: 82705.485 | BP18: 0 | BQ18: 0 | BR18: - | BS18: 123398.41 | BT18: -163.435 | BU18: -756.0305 | BV18: 123398.41 | BW18: -163.435 | BX18: 756.0305 | BY18: 123561.84 | CA18: 0 | CB18: 0 | CC18: - | CD18: 46536.18 | CE18: -163.435 | CF18: -285.73815 | CG18: 46536.18 | CH18: -163.435 | CI18: 285.73815 | CJ18: 46699.615
A19: Resultado Bari Capital | B19: 0 | C19: 0 | D19: - | E19: 168678.17 | F19: 168678.17 | G19: 0 | H19: 168678.17 | I19: 168678.17 | J19: 0 | K19: 0 | M19: 0 | N19: 0 | O19: - | P19: -629.72 | Q19: 52800 | R19: -1.0119265 | S19: -629.72 | T19: 52800 | U19: -1.0119265 | V19: -53429.72 | X19: 0 | Y19: 0 | Z19: - | AA19: -262478.75 | AB19: 19800 | AC19: -14.256503 | AD19: -262478.75 | AE19: 19800 | AF19: -14.256503 | AG19: -282278.75 | AI19: 0 | AJ19: 0 | AK19: - | AL19: 23664.61 | AM19: 19800 | AN19: 0.19518232 | AO19: 23664.61 | AP19: 19800 | AQ19: 0.19518232 | AR19: 3864.61 | AT19: 0 | AU19: 0 | AV19: - | AW19: -87553.01 | AX19: 19800 | AY19: -5.4218692 | AZ19: -87553.01 | BA19: 19800 | BB19: -5.4218692 | BC19: -107353.01 | BE19: 0 | BF19: 0 | BG19: - | BH19: 15935.41 | BI19: 19800 | BJ19: -0.19518131 | BK19: 15935.41 | BL19: 19800 | BM19: -0.19518131 | BN19: -3864.59 | BP19: 0 | BQ19: 0 | BR19: - | BS19: 24659.56 | BT19: 19800 | BU19: 0.24543232 | BV19: 24659.56 | BW19: 19800 | BX19: 0.24543232 | BY19: 4859.56 | CA19: 0 | CB19: 0 | CC19: - | CD19: 16626.2 | CE19: 19800 | CF19: -0.16029293 | CG19: 16626.2 | CH19: 19800 | CI19: -0.16029293 | CJ19: -3173.8
A20: Resultado Sec | B20: 0 | C20: 0 | D20: - | E20: 87060.33 | F20: 87060.33 | G20: 0 | H20: 87060.33 | I20: 87060.33 | J20: 0 | K20: 0 | M20: 0 | N20: 0 | O20: - | P20: 243037.75 | Q20: 210147.87 | R20: 0.15650829 | S20: 243037.75 | T20: 210147.87 | U20: 0.15650829 | V20: 32889.883 | X20: 0 | Y20: 0 | Z20: - | AA20: 521291.11 | AB20: 210147.87 | AC20: 1.480592 | AD20: 521291.11 | AE20: 210147.87 | AF20: 1.480592 | AG20: 311143.24 | AI20: 0 | AJ20: 0 | AK20: - | AL20: 725407.97 | AM20: 210147.87 | AN20: 2.4518931 | AO20: 725407.97 | AP20: 210147.87 | AQ20: 2.4518931 | AR20: 515260.1 | AT20: 0 | AU20: 0 | AV20: - | AW20: 597908.29 | AX20: 210147.87 | AY20: 1.845179 | AZ20: 597908.29 | BA20: 210147.87 | BB20: 1.845179 | BC20: 387760.42 | BE20: 0 | BF20: 0 | BG20: - | BH20: 1829477.4 | BI20: 210147.87 | BJ20: 7.7056673 | BK20: 1829477.4 | BL20: 210147.87 | BM20: 7.7056673 | BN20: 1619329.5 | BP20: 0 | BQ20: 0 | BR20: - | BS20: 750956.22 | BT20: 210147.87 | BU20: 2.5734658 | BV20: 750956.22 | BW20: 210147.87 | BX20: 2.5734658 | BY20: 540808.35 | CA20: 0 | CB20: 0 | CC20: - | CD20: 1263134.2 | CE20: 210147.87 | CF20: 5.0106927 | CG20: 1263134.2 | CH20: 210147.87 | CI20: 5.0106927 | CJ20: 1052986.4
A21: DESPESAS DE ORIGINAÇÃO | B21: -4115579.3 | C21: -4007372 | D21: 0.027002072 | E21: -13893293 | F21: -13901145 | G21: -0.0005648475 | H21: -18008872 | I21: -17908517 | J21: 0.005603776 | K21: 100355.32 | M21: -3458538.1 | N21: -3324628.9 | O21: 0.040277941 | P21: -11194223 | Q21: -12699380 | R21: -0.11852208 | S21: -14652761 | T21: -16024009 | U21: -0.085574575 | V21: -1371247.8 | X21: -4803644.1 | Y21: -4620516.9 | Z21: 0.039633491 | AA21: -17862654 | AB21: -15301310 | AC21: 0.16739376 | AD21: -22666298 | AE21: -19921827 | AF21: 0.13776202 | AG21: 2744471.1 | AI21: -4383516.3 | AJ21: -4409897.3 | AK21: -0.0059822152 | AL21: -17657422 | AM21: -13769320 | AN21: 0.28237426 | AO21: -22040938 | AP21: -18179217 | AQ21: 0.21242502 | AR21: 3861720.6 | AT21: -4480613.7 | AU21: -4475939 | AV21: 0.0010444098 | AW21: -15739911 | AX21: -13995733 | AY21: 0.12462214 | AZ21: -20220525 | BA21: -18471672 | BB21: 0.094677562 | BC21: 1748852.9 | BE21: -4804004.9 | BF21: -4848789.1 | BG21: -0.0092361716 | BH21: -17194338 | BI21: -14559699 | BJ21: 0.1809542 | BK21: -21998343 | BL21: -19408488 | BM21: 0.13343927 | BN21: 2589854.5 | BP21: -5126638.3 | BQ21: -5185752.6 | BR21: -0.011399367 | BS21: -15385685 | BT21: -16115171 | BU21: -0.045267019 | BV21: -20512323 | BW21: -21300923 | BX21: -0.037021871 | BY21: -788600.05 | CA21: -5025450.5 | CB21: -4722997.6 | CC21: 0.064038339 | CD21: -13507739 | CE21: -15393726 | CF21: -0.12251655 | CG21: -18533190 | CH21: -20116723 | CI21: -0.078717256 | CJ21: -1583533.2
A22: Despesa de Captação* | B22: -4115579.3 | C22: -4007372 | D22: 0.027002072 | E22: -13893293 | F22: -13901145 | G22: -0.0005648475 | H22: -18008872 | I22: -17908517 | J22: 0.005603776 | K22: 100355.32 | M22: -3458538.1 | N22: -3324628.9 | O22: 0.040277941 | P22: -11194223 | Q22: -12699380 | R22: -0.11852208 | S22: -14652761 | T22: -16024009 | U22: -0.085574575 | V22: -1371247.8 | X22: -4803644.1 | Y22: -4620516.9 | Z22: 0.039633491 | AA22: -17862654 | AB22: -15301310 | AC22: 0.16739376 | AD22: -22666298 | AE22: -19921827 | AF22: 0.13776202 | AG22: 2744471.1 | AI22: -4383516.3 | AJ22: -4409897.3 | AK22: -0.0059822152 | AL22: -17657422 | AM22: -13769320 | AN22: 0.28237426 | AO22: -22040938 | AP22: -18179217 | AQ22: 0.21242502 | AR22: 3861720.6 | AT22: -4480613.7 | AU22: -4475939 | AV22: 0.0010444098 | AW22: -15739911 | AX22: -13995733 | AY22: 0.12462214 | AZ22: -20220525 | BA22: -18471672 | BB22: 0.094677562 | BC22: 1748852.9 | BE22: -4804004.9 | BF22: -4848789.1 | BG22: -0.0092361716 | BH22: -17194338 | BI22: -14559699 | BJ22: 0.1809542 | BK22: -21998343 | BL22: -19408488 | BM22: 0.13343927 | BN22: 2589854.5 | BP22: -5126638.3 | BQ22: -5185752.6 | BR22: -0.011399367 | BS22: -15385685 | BT22: -16115171 | BU22: -0.045267019 | BV22: -20512323 | BW22: -21300923 | BX22: -0.037021871 | BY22: -788600.05 | CA22: -5025450.5 | CB22: -4722997.6 | CC22: 0.064038339 | CD22: -13507739 | CE22: -15393726 | CF22: -0.12251655 | CG22: -18533190 | CH22: -20116723 | CI22: -0.078717256 | CJ22: -1583533.2
